#VRML_SIM R2023b utf8

EXTERNPROTO "https://raw.githubusercontent.com/cyberbotics/webots/R2023a/projects/objects/backgrounds/protos/TexturedBackground.proto"
EXTERNPROTO "https://raw.githubusercontent.com/cyberbotics/webots/R2023a/projects/objects/backgrounds/protos/TexturedBackgroundLight.proto"
EXTERNPROTO "https://raw.githubusercontent.com/cyberbotics/webots/R2023a/projects/objects/floors/protos/RectangleArena.proto"

WorldInfo {
}
Viewpoint {
  orientation -0.12189969972313724 -0.7933286243782466 0.5964647155947517 5.571155457842414
  position -2.3389607904306327 0.803029199026391 1.7405964564146623
}
TexturedBackground {
  texture "empty_office"
}
TexturedBackgroundLight {
}
RectangleArena {
}
DEF ROBOT Robot {
  translation 3.807998890368193e-06 -1.1901140085567304e-06 0.039512576924391314
  rotation -0.1861270209167696 0.6947330780734129 0.6947680780773462 -2.7734253071795862
  children [
    Camera {
      name "red_camera"
      recognitionColors [
        1 1 0
        0 1 0
        0 0 1
        1 0 0
      ]
      fieldOfView 1.57
      width 80
      height 80
      recognition Recognition {
        maxObjects 4
      }
    }
    InertialUnit {
      name "inertial_unit"
    }
    DEF HINGE_COVER Solid {
      translation 0 0.03 -3.469446951953614e-18
      rotation 0 1 0 -1.5707953071795862
      children [
        Shape {
          appearance PBRAppearance {
            baseColor 0 0.6509803921568628 1
          }
          geometry Box {
            size 0.030000000000000002 0.019999999999999997 0.05
          }
        }
      ]
      name "hingeCover"
    }
    DEF BODY Shape {
      appearance PBRAppearance {
        baseColor 0.917647 0.145098 0.145098
        roughness 1
        metalness 0
      }
      geometry Box {
        size 0.2 0.05 0.08
      }
    }
    DEF WHEEL1 HingeJoint {
      jointParameters HingeJointParameters {
        position 4.537463795243942e-12
        axis 0 0 1
        anchor 0.06 0 0.05
      }
      device [
        RotationalMotor {
          name "wheel1"
        }
      ]
      endPoint Solid {
        translation 0.060001004644816586 1.3392769184314884e-05 0.050000010543824816
        rotation 1.767102257305865e-08 -1.7671188841531882e-08 0.9999999999999997 1.570800043243364
        children [
          DEF WHEEL Shape {
            appearance PBRAppearance {
              baseColor 0.305882 0.898039 0.25098
              roughness 1
              metalness 0
            }
            geometry Cylinder {
              height 0.02
              radius 0.04
              subdivision 24
            }
          }
        ]
        boundingObject USE WHEEL
        physics Physics {
        }
      }
    }
    DEF WHEEL2 HingeJoint {
      jointParameters HingeJointParameters {
        position -5.015476829643425e-12
        axis 0 0 1
        anchor -0.06 0 0.05
      }
      device [
        RotationalMotor {
          name "wheel2"
        }
      ]
      endPoint Solid {
        translation -0.06000109599395417 7.616338725002354e-07 0.05000000952472374
        rotation 1.7609574010003707e-08 -1.7609746115867005e-08 0.9999999999999997 1.570799956733921
        children [
          USE WHEEL
        ]
        name "solid(1)"
        boundingObject USE WHEEL
        physics Physics {
        }
      }
    }
    DEF WHEEL3 HingeJoint {
      jointParameters HingeJointParameters {
        position 4.5639729743744876e-12
        axis 0 0 1
        anchor 0.06 0 -0.05
      }
      device [
        RotationalMotor {
          name "wheel3"
        }
      ]
      endPoint Solid {
        translation 0.060001003799097515 1.3392659934678373e-05 -0.05000000738328558
        rotation -1.7671313697098898e-08 1.7671472870706606e-08 0.9999999999999997 1.5708000432446703
        children [
          USE WHEEL
        ]
        name "solid(2)"
        boundingObject USE WHEEL
        physics Physics {
        }
      }
    }
    DEF WHEEL4 HingeJoint {
      jointParameters HingeJointParameters {
        position -4.988797675945358e-12
        axis 0 0 1
        anchor -0.06 0 -0.05
      }
      device [
        RotationalMotor {
          name "wheel4"
        }
      ]
      endPoint Solid {
        translation -0.060001096839924384 7.61524622761122e-07 -0.05000000839401549
        rotation -1.7609961527745086e-08 1.7610133456949922e-08 0.9999999999999997 1.570799956735277
        children [
          USE WHEEL
        ]
        name "solid(3)"
        boundingObject USE WHEEL
        physics Physics {
        }
      }
    }
  ]
  boundingObject USE BODY
  physics Physics {
    density -1
    mass 2
  }
  controller "camera_field_of_view"
  supervisor TRUE
}
Solid {
  translation 0.37 -0.38 0
  children [
    Shape {
      appearance Appearance {
        material Material {
          diffuseColor 1 0 0
        }
      }
      geometry Box {
        size 0.1 0.1 0.1
      }
    }
  ]
  name "red block"
  boundingObject Box {
    size 0.1 0.1 0.1
  }
  recognitionColors [
    1 0 0
  ]
}
Solid {
  translation 0.37 0.37 0
  children [
    Shape {
      appearance Appearance {
        material Material {
          diffuseColor 0 0 1
        }
      }
      geometry Box {
        size 0.1 0.1 0.1
      }
    }
  ]
  name "blue block"
  model "blue_object"
  boundingObject Box {
    size 0.1 0.1 0.1
  }
  recognitionColors [
    0 0 1
  ]
}
Solid {
  translation -0.37 0.37 0
  children [
    Shape {
      appearance Appearance {
        material Material {
          diffuseColor 0 1 0
        }
      }
      geometry Box {
        size 0.1 0.1 0.1
      }
    }
  ]
  name "green_block"
  model "green_object"
  boundingObject Box {
    size 0.1 0.1 0.0001
  }
  recognitionColors [
    0 1 0
  ]
}
Solid {
  translation -0.37 -0.37 0
  children [
    Shape {
      appearance Appearance {
        material Material {
          diffuseColor 1 1 0
        }
      }
      geometry Box {
        size 0.1 0.1 0.1
      }
    }
  ]
  name "yellow_block"
  model "yellow_object"
  boundingObject Box {
    size 0.1 0.1 0.0001
  }
  recognitionColors [
    1 1 0
  ]
}
